Workbook

Sheet Cover Page
A1: SENTICRAG | B1: Kế hoạch 14 tuần — 1 người
A2: Bắt đầu | B2: 46321 | C2: Bàn giao | D2: 46416 | E2: Chatbot trước • 75 dòng công việc • đầy đủ input/output, module và công nghệ
A4: Mốc | B4: Giai đoạn | C4: Bắt đầu | D4: Kết thúc | E4: Kết quả cần bàn giao | F4: Tuần | G4: Gate
A5: M0 | B5: Thiết kế chatbot và khóa phạm vi | C5: 46321 | D5: 46325 | E5: Thiết kế chatbot, contract v1, wireframe, backlog, quyết định kỹ thuật và bộ kịch bản nghiệm thu. | F5: W1–W1 | G5: G0
A6: M1 | B6: Chuẩn hóa dữ liệu chính sách cho chatbot | C6: 46328 | D6: 46332 | E6: PolicyDocument/PolicyChunk đã duyệt; catalog nguồn; ingest report; policy-QA và privacy fixtures. | F6: W2–W2 | G6: G1
A7: M2 | B7: Chatbot RAG đầu tiên chạy xuyên suốt | C7: 46335 | D7: 46346 | E7: Chat UI + API + history + retrieval + grounded generation; Docker demo; báo cáo benchmark ban đầu. | F7: W3–W4 | G7: G2
A8: M3 | B8: Chatbot theo đơn hàng và Copilot CSKH | C8: 46349 | D8: 46360 | E8: Policy engine + customer tools + FSM + Agent Workspace; ticket/action/outcome và phản hồi được lưu. | F8: W5–W6 | G8: G3
A9: M4 | B9: ABSA và ingestion toàn corpus | C9: 46363 | D9: 46374 | E9: Baseline + candidate ABSA, report, model card; predictions có version; async worker + router; triage tự động. | F9: W7–W8 | G9: G4
A10: M5 | B10: Dashboard toàn corpus và điều tra bằng evidence | C10: 46377 | D10: 46381 | E10: Analyst/PM dashboard, population/denominator, anomaly alert, drill-down giữ nguyên filters, benchmark review retrieval. | F10: W9–W9 | G10: G5
A11: M6 | B11: GraphRAG và quản trị tri thức | C11: 46384 | D11: 46395 | E11: Ontology v1 + Neo4j + graph traversal; analyst/steward UI; knowledge publish/rollback; chatbot có evidence graph. | F11: W10–W11 | G11: G6
A12: M7 | B12: Closed-loop feedback và cải thiện mô hình | C12: 46398 | D12: 46402 | E12: Versioned annotation datasets; active-learning queue; một retraining/eval cycle; drift monitors và publish decision. | F12: W12–W12 | G12: G7
A13: M8 | B13: Tích hợp, vận hành và bàn giao | C13: 46405 | D13: 46416 | E13: Release bundle, 5 UAT demos, eval suite, deploy/IaC package, runbooks, rollback evidence và coverage ledger. | F13: W13–W14 | G13: G8
B15: Mở các sheet chi tiết bên dưới:
E16: Mục tiêu: chatbot RAG đầu tiên chạy được cuối tuần 4 — 20/11/2026.
B17: Milestones
B18: Milestone Details | E18: 60 ngày công + 9 ngày dự phòng + 1 ngày nghỉ dự kiến 01/01. Các công việc xếp nối tiếp cho một người.
B19: WBS
B20: Task Details | E20: Xem Task Details để đọc input, các bước làm, output, công nghệ và điều kiện hoàn thành từng task.
B21: Capacity
B22: Module Catalog | E22: Chỉnh Task Status tại WBS, cột J. Những sheet khác lấy trạng thái từ WBS.
B23: IO Contracts
B24: Proposal Traceability | E24: Kế hoạch chưa phải kết quả đã triển khai; các target chất lượng, cloud và KPI kinh doanh cần bằng chứng nghiệm thu.
B25: Acceptance Gates
B26: Data Plan
B27: Tech Stack
B28: Decisions
B29: Extensions
B30: Source Register
B31: Notes

Sheet Milestones
A1: MILESTONES | các giai đoạn và gate bàn giao
A2: 1 người • 26/10/2026–31/01/2027 • 14 tuần • ngày T2–T6; 01/01 dành cho nghỉ dự kiến • màu biểu thị trạng thái kế hoạch
A3: ← Cover Page
B4: Người thực hiện: Trần Đình Khương | mọi vai trò kỹ thuật đều do cùng một người đảm nhiệm.
B5: Not Started / In Progress / Done / Blocked / Deferred / Contingency
B6: Lịch và effort tính theo 0,5 ngày; xem Task Details để biết buổi bắt đầu và dependency.
B8: Task | F8: Start date | G8: End date | H8: Responsibility | I8: Deliverable | J8: Task Status | K8: W1 | R8: W2 | Y8: W3 | AF8: W4 | AM8: W5 | AT8: W6 | BA8: W7 | BH8: W8 | BO8: W9 | BV8: W10 | CC8: W11 | CJ8: W12 | CQ8: W13 | CX8: W14
K9: T2 | L9: T3 | M9: T4 | N9: T5 | O9: T6 | P9: T7 | Q9: CN | R9: T2 | S9: T3 | T9: T4 | U9: T5 | V9: T6 | W9: T7 | X9: CN | Y9: T2 | Z9: T3 | AA9: T4 | AB9: T5 | AC9: T6 | AD9: T7 | AE9: CN | AF9: T2 | AG9: T3 | AH9: T4 | AI9: T5 | AJ9: T6 | AK9: T7 | AL9: CN | AM9: T2 | AN9: T3 | AO9: T4 | AP9: T5 | AQ9: T6 | AR9: T7 | AS9: CN | AT9: T2 | AU9: T3 | AV9: T4 | AW9: T5 | AX9: T6 | AY9: T7 | AZ9: CN | BA9: T2 | BB9: T3 | BC9: T4 | BD9: T5 | BE9: T6 | BF9: T7 | BG9: CN | BH9: T2 | BI9: T3 | BJ9: T4 | BK9: T5 | BL9: T6 | BM9: T7 | BN9: CN | BO9: T2 | BP9: T3 | BQ9: T4 | BR9: T5 | BS9: T6 | BT9: T7 | BU9: CN | BV9: T2 | BW9: T3 | BX9: T4 | BY9: T5 | BZ9: T6 | CA9: T7 | CB9: CN | CC9: T2 | CD9: T3 | CE9: T4 | CF9: T5 | CG9: T6 | CH9: T7 | CI9: CN | CJ9: T2 | CK9: T3 | CL9: T4 | CM9: T5 | CN9: T6 | CO9: T7 | CP9: CN | CQ9: T2 | CR9: T3 | CS9: T4 | CT9: T5 | CU9: T6 | CV9: T7 | CW9: CN | CX9: T2 | CY9: T3 | CZ9: T4 | DA9: T5 | DB9: T6 | DC9: T7 | DD9: CN
K10: 46321 | L10: 46322 | M10: 46323 | N10: 46324 | O10: 46325 | P10: 46326 | Q10: 46327 | R10: 46328 | S10: 46329 | T10: 46330 | U10: 46331 | V10: 46332 | W10: 46333 | X10: 46334 | Y10: 46335 | Z10: 46336 | AA10: 46337 | AB10: 46338 | AC10: 46339 | AD10: 46340 | AE10: 46341 | AF10: 46342 | AG10: 46343 | AH10: 46344 | AI10: 46345 | AJ10: 46346 | AK10: 46347 | AL10: 46348 | AM10: 46349 | AN10: 46350 | AO10: 46351 | AP10: 46352 | AQ10: 46353 | AR10: 46354 | AS10: 46355 | AT10: 46356 | AU10: 46357 | AV10: 46358 | AW10: 46359 | AX10: 46360 | AY10: 46361 | AZ10: 46362 | BA10: 46363 | BB10: 46364 | BC10: 46365 | BD10: 46366 | BE10: 46367 | BF10: 46368 | BG10: 46369 | BH10: 46370 | BI10: 46371 | BJ10: 46372 | BK10: 46373 | BL10: 46374 | BM10: 46375 | BN10: 46376 | BO10: 46377 | BP10: 46378 | BQ10: 46379 | BR10: 46380 | BS10: 46381 | BT10: 46382 | BU10: 46383 | BV10: 46384 | BW10: 46385 | BX10: 46386 | BY10: 46387 | BZ10: 46388 | CA10: 46389 | CB10: 46390 | CC10: 46391 | CD10: 46392 | CE10: 46393 | CF10: 46394 | CG10: 46395 | CH10: 46396 | CI10: 46397 | CJ10: 46398 | CK10: 46399 | CL10: 46400 | CM10: 46401 | CN10: 46402 | CO10: 46403 | CP10: 46404 | CQ10: 46405 | CR10: 46406 | CS10: 46407 | CT10: 46408 | CU10: 46409 | CV10: 46410 | CW10: 46411 | CX10: 46412 | CY10: 46413 | CZ10: 46414 | DA10: 46415 | DB10: 46416 | DC10: 46417 | DD10: 46418
B11: M0 | E11: Thiết kế chatbot và khóa phạm vi | F11: 46321 | G11: 46325 | H11: Trần Đình Khương | I11: Thiết kế chatbot, contract v1, wireframe, backlog, quyết định kỹ thuật và bộ kịch bản nghiệm thu. | J11: ='WBS'!J11 | K11: • | L11: • | M11: • | N11: • | O11: •
D12: M0.G | E12: G0 — Review, nghiệm thu và báo cáo giai đoạn | F12: 46324 | G12: 46324 | H12: Trần Đình Khương | I12: docs/reports/milestones/m0-review.md; checklist; demo; manifest phiên bản 0.5 ngày • PM • sau M0.4 | J12: ='WBS'!J16 | N12: ◆
B13: M1 | E13: Chuẩn hóa dữ liệu chính sách cho chatbot | F13: 46328 | G13: 46332 | H13: Trần Đình Khương | I13: PolicyDocument/PolicyChunk đã duyệt; catalog nguồn; ingest report; policy-QA và privacy fixtures. | J13: ='WBS'!J18 | R13: • | S13: • | T13: • | U13: • | V13: •
D14: M1.G | E14: G1 — Review, nghiệm thu và báo cáo giai đoạn | F14: 46331 | G14: 46331 | H14: Trần Đình Khương | I14: docs/reports/milestones/m1-review.md; checklist; demo; manifest phiên bản 0.5 ngày • PM • sau M1.4 | J14: ='WBS'!J23 | U14: ◆
B15: M2 | E15: Chatbot RAG đầu tiên chạy xuyên suốt | F15: 46335 | G15: 46346 | H15: Trần Đình Khương | I15: Chat UI + API + history + retrieval + grounded generation; Docker demo; báo cáo benchmark ban đầu. | J15: ='WBS'!J25 | Y15: • | Z15: • | AA15: • | AB15: • | AC15: • | AF15: • | AG15: • | AH15: • | AI15: • | AJ15: •
D16: M2.G | E16: G2 — Review, nghiệm thu và báo cáo giai đoạn | F16: 46345 | G16: 46345 | H16: Trần Đình Khương | I16: docs/reports/milestones/m2-review.md; checklist; demo; manifest phiên bản 0.5 ngày • PM • sau M2.8 | J16: ='WBS'!J34 | AI16: ◆
B17: M3 | E17: Chatbot theo đơn hàng và Copilot CSKH | F17: 46349 | G17: 46360 | H17: Trần Đình Khương | I17: Policy engine + customer tools + FSM + Agent Workspace; ticket/action/outcome và phản hồi được lưu. | J17: ='WBS'!J36 | AM17: • | AN17: • | AO17: • | AP17: • | AQ17: • | AT17: • | AU17: • | AV17: • | AW17: • | AX17: •
D18: M3.G | E18: G3 — Review, nghiệm thu và báo cáo giai đoạn | F18: 46359 | G18: 46359 | H18: Trần Đình Khương | I18: docs/reports/milestones/m3-review.md; checklist; demo; manifest phiên bản 0.5 ngày • PM • sau M3.8 | J18: ='WBS'!J45 | AW18: ◆
B19: M4 | E19: ABSA và ingestion toàn corpus | F19: 46363 | G19: 46374 | H19: Trần Đình Khương | I19: Baseline + candidate ABSA, report, model card; predictions có version; async worker + router; triage tự động. | J19: ='WBS'!J47 | BA19: • | BB19: • | BC19: • | BD19: • | BE19: • | BH19: • | BI19: • | BJ19: • | BK19: • | BL19: •
D20: M4.G | E20: G4 — Review, nghiệm thu và báo cáo giai đoạn | F20: 46373 | G20: 46373 | H20: Trần Đình Khương | I20: docs/reports/milestones/m4-review.md; checklist; demo; manifest phiên bản 0.5 ngày • PM • sau M4.7 | J20: ='WBS'!J55 | BK20: ◆
B21: M5 | E21: Dashboard toàn corpus và điều tra bằng evidence | F21: 46377 | G21: 46381 | H21: Trần Đình Khương | I21: Analyst/PM dashboard, population/denominator, anomaly alert, drill-down giữ nguyên filters, benchmark review retrieval. | J21: ='WBS'!J57 | BO21: • | BP21: • | BQ21: • | BR21: • | BS21: •
D22: M5.G | E22: G5 — Review, nghiệm thu và báo cáo giai đoạn | F22: 46380 | G22: 46380 | H22: Trần Đình Khương | I22: docs/reports/milestones/m5-review.md; checklist; demo; manifest phiên bản 0.5 ngày • PM • sau M5.4 | J22: ='WBS'!J62 | BR22: ◆
B23: M6 | E23: GraphRAG và quản trị tri thức | F23: 46384 | G23: 46395 | H23: Trần Đình Khương | I23: Ontology v1 + Neo4j + graph traversal; analyst/steward UI; knowledge publish/rollback; chatbot có evidence graph. | J23: ='WBS'!J64 | BV23: • | BW23: • | BX23: • | BY23: • | BZ23: • | CC23: • | CD23: • | CE23: • | CF23: • | CG23: •
D24: M6.G | E24: G6 — Review, nghiệm thu và báo cáo giai đoạn | F24: 46395 | G24: 46395 | H24: Trần Đình Khương | I24: docs/reports/milestones/m6-review.md; checklist; demo; manifest phiên bản 0.5 ngày • PM • sau M6.9 | J24: ='WBS'!J74 | CG24: ◆
B25: M7 | E25: Closed-loop feedback và cải thiện mô hình | F25: 46398 | G25: 46402 | H25: Trần Đình Khương | I25: Versioned annotation datasets; active-learning queue; một retraining/eval cycle; drift monitors và publish decision. | J25: ='WBS'!J76 | CJ25: • | CK25: • | CL25: • | CM25: • | CN25: •
D26: M7.G | E26: G7 — Review, nghiệm thu và báo cáo giai đoạn | F26: 46401 | G26: 46401 | H26: Trần Đình Khương | I26: docs/reports/milestones/m7-review.md; checklist; demo; manifest phiên bản 0.5 ngày • PM • sau M7.5 | J26: ='WBS'!J82 | CM26: ◆
B27: M8 | E27: Tích hợp, vận hành và bàn giao | F27: 46405 | G27: 46416 | H27: Trần Đình Khương | I27: Release bundle, 5 UAT demos, eval suite, deploy/IaC package, runbooks, rollback evidence và coverage ledger. | J27: ='WBS'!J84 | CQ27: • | CR27: • | CS27: • | CT27: • | CU27: • | CX27: • | CY27: • | CZ27: • | DA27: • | DB27: •
D28: M8.G | E28: G8 — Review, nghiệm thu và báo cáo giai đoạn | F28: 46414 | G28: 46414 | H28: Trần Đình Khương | I28: docs/reports/milestones/m8-review.md; checklist; demo; manifest phiên bản 0.5 ngày • PM • sau M8.8 | J28: ='WBS'!J93 | CZ28: ◆

Sheet Milestone Details
A1: MILESTONE DETAILS | input, output và cách hoàn thành
A2: Mọi giai đoạn triển khai nối tiếp bởi một người. Entry gate không đạt thì các việc phụ thuộc phải dừng/sửa hoặc rebaseline.
A3: ← Cover Page
A4: ID | B4: Giai đoạn | C4: Tuần | D4: Bắt đầu | E4: Kết thúc | F4: Mục tiêu | G4: Entry criteria / phụ thuộc | H4: Input | I4: Output / bàn giao | J4: Modules | K4: Công nghệ | L4: Demo / cách nghiệm thu | M4: User story coverage | N4: Ngày công | O4: Gate
A5: M0 | B5: Thiết kế chatbot và khóa phạm vi | C5: W1–W1 | D5: 46321 | E5: 46325 | F5: Chốt kiến trúc hội thoại trước, hợp đồng dùng chung và tiêu chí 14 tuần cho một người. | G5: START; 1 người, 5 ngày làm việc/tuần; kiểm kê API key, máy/GPU, cloud và quyền dữ liệu. | H5: Architecture, 5 user stories, mã khung hiện tại, dữ liệu crawl và mẫu Excel. | I5: Thiết kế chatbot, contract v1, wireframe, backlog, quyết định kỹ thuật và bộ kịch bản nghiệm thu. | J5: MOD-01, MOD-03, MOD-04, MOD-12 | K5: FastAPI/Pydantic; PostgreSQL; React/TypeScript (đề xuất); Docker Compose | L5: Walkthrough 3 lượt: hỏi chính sách → hỏi tiếp → thiếu bằng chứng/chuyển người xử lý. | M5: US-BUY-01 nền tảng; thiết kế đủ US-AGENT/ANALYST/PM/STEWARD | N5: 4 core + 1 reserve | O5: G0
A6: M1 | B6: Chuẩn hóa dữ liệu chính sách cho chatbot | C6: W2–W2 | D6: 46328 | E6: 46332 | F6: Biến dữ liệu crawl thành knowledge base được kiểm duyệt và truy nguồn. | G6: G0 PASS; tài liệu có quyền sử dụng; chốt phạm vi demo 5–10 policy (~30 điều khoản). | H6: Raw HTML/text/page.json/report từ Data_crawling; tài liệu do người dùng cung cấp. | I6: PolicyDocument/PolicyChunk đã duyệt; catalog nguồn; ingest report; policy-QA và privacy fixtures. | J6: MOD-02, MOD-06, MOD-12 | K6: Python parser; Pydantic; PostgreSQL; JSONL; regex + NER | L6: Từ URL gốc → nội dung sạch → đoạn trích chứa đủ điều kiện/ngoại lệ. | M6: US-BUY-01 / US-AGENT-01 nguồn chính sách; US-STEWARD-01 duyệt tài liệu | N6: 4 core + 1 reserve | O6: G1
A7: M2 | B7: Chatbot RAG đầu tiên chạy xuyên suốt | C7: W3–W4 | D7: 46335 | E7: 46346 | F7: Bàn giao chatbot tiếng Việt có hội thoại, evidence và fallback trên dữ liệu thật đã làm sạch. | G7: G1 PASS; API key/provider hoặc mô hình local chạy được; máy đủ embedding corpus nhỏ. | H7: Policy chunks approved, contracts/chat wireframe, golden sets, provider cấu hình được. | I7: Chat UI + API + history + retrieval + grounded generation; Docker demo; báo cáo benchmark ban đầu. | J7: MOD-01, MOD-03, MOD-04, MOD-12 | K7: FastAPI; React/TypeScript; PostgreSQL; Redis; Qdrant; BM25/RRF; LLM API; BGE candidate | L7: Hỏi đổi trả → hỏi tiếp ngoại lệ → hiện nguồn; câu không đủ evidence → clarification/handoff. | M7: US-BUY-01 mức policy Q&A; US-AGENT-01 evidence nền tảng; chưa đủ full story | N7: 9 core + 1 reserve | O7: G2
A8: M3 | B8: Chatbot theo đơn hàng và Copilot CSKH | C8: W5–W6 | D8: 46349 | E8: 46360 | F8: Thêm quyết định chính sách có kiểm soát, chuyển người xử lý và lưu outcome. | G8: G2 PASS; data demo được đánh dấu synthetic; quyền CRM thật chỉ cần khi chọn live adapter. | H8: Chatbot G2; policy clauses; seed products/orders/customers; resolution scenarios. | I8: Policy engine + customer tools + FSM + Agent Workspace; ticket/action/outcome và phản hồi được lưu. | J8: MOD-01, MOD-03, MOD-05, MOD-06, MOD-11, MOD-12 | K8: PostgreSQL; deterministic rules; FastAPI; MCP adapters; React; bounded FSM | L8: Đơn còn hạn → draft có điều kiện; hết hạn/không sở hữu đơn → không hứa quyền lợi; agent sửa/duyệt/escalate. | M8: US-BUY-01 resolution path; US-AGENT-01 workspace/outcomes; ABSA tự động bổ sung M4 | N8: 9 core + 1 reserve | O8: G3
A9: M4 | B9: ABSA và ingestion toàn corpus | C9: W7–W8 | D9: 46363 | E9: 46374 | F9: Tạo dữ liệu sentiment/aspect thật để triage và thống kê toàn bộ corpus. | G9: G3 PASS; chốt dataset/license/splits tại M0; compute đã sẵn hoặc candidate không chạy ghi BLOCKED. | H9: Review/ticket/chat đã mask; UIT-ViSFD/ViSD4SA được phép sử dụng; taxonomy; corrections. | I9: Baseline + candidate ABSA, report, model card; predictions có version; async worker + router; triage tự động. | J9: MOD-02, MOD-07, MOD-12 | K9: scikit-learn; PyTorch/Transformers/PhoBERT candidate; PostgreSQL; Redis Streams | L9: “Máy đẹp nhưng pin yếu” → hai aspect/polarity; toàn corpus được xử lý, ticket card có triage thật. | M9: Hoàn thiện BUY-AC-01; US-AGENT-01 triage; nền US-ANALYST-01/US-PM-01 | N9: 9 core + 1 reserve | O9: G4
A10: M5 | B10: Dashboard toàn corpus và điều tra bằng evidence | C10: W9–W9 | D10: 46377 | E10: 46381 | F10: Nối thống kê toàn bộ dữ liệu với truy xuất các trường hợp đại diện. | G10: G4 PASS hoặc demo hạn chế được ghi rõ; model/index snapshot đồng nhất. | H10: Versioned ABSA predictions, review metadata, ticket outcomes, retrieval service. | I10: Analyst/PM dashboard, population/denominator, anomaly alert, drill-down giữ nguyên filters, benchmark review retrieval. | J10: MOD-04, MOD-09, MOD-10 | K10: PostgreSQL aggregates; React charts; Qdrant; RRF/reranker; scheduled worker | L10: Click spike pin theo firmware → xem 5–10 cases cùng cohort; không dùng Top-K làm tỷ lệ toàn corpus. | M10: US-ANALYST-01 quant→qual; US-PM-01 trend/outcome; graph enrichment ở M6 | N10: 4 core + 1 reserve | O10: G5
A11: M6 | B11: GraphRAG và quản trị tri thức | C11: W10–W11 | D11: 46384 | E11: 46395 | F11: Liên kết issue/version/cause/policy/resolution, đưa kết luận đã duyệt trở lại chatbot. | G11: G5 PASS; ontology canonical thống nhất giữa blueprint và schema rút gọn. | H11: Evidence cohorts, taxonomy, product versions, policy registry, confirmed synthetic known issues. | I11: Ontology v1 + Neo4j + graph traversal; analyst/steward UI; knowledge publish/rollback; chatbot có evidence graph. | J11: MOD-04, MOD-06, MOD-08, MOD-10, MOD-11 | K11: Neo4j; Cypher; Python driver; PostgreSQL approval log; React | L11: Spike → analyst hypothesis → steward approve → publish → ticket mới nhận draft dựa trên cause confirmed. | M11: Hoàn thiện US-ANALYST-01, US-STEWARD-01; graph context cho US-BUY/AGENT/PM | N11: 9 core + 1 reserve | O11: G6
A12: M7 | B12: Closed-loop feedback và cải thiện mô hình | C12: W12–W12 | D12: 46398 | E12: 46402 | F12: Đưa chỉnh sửa đã duyệt vào dữ liệu đánh giá/huấn luyện và đo chất lượng qua phiên bản. | G12: G6 PASS; có correction fixtures và giới hạn training budget; test set vẫn locked. | H12: Agent edits, ABSA corrections, retrieval judgments, outcome events, stewardship logs. | I12: Versioned annotation datasets; active-learning queue; một retraining/eval cycle; drift monitors và publish decision. | J12: MOD-07, MOD-09, MOD-11, MOD-12 | K12: PostgreSQL; Python export/retrain; existing model pipeline; OpenTelemetry/Prometheus | L12: Sửa nhãn → review → export dataset v2 → train candidate → regression → giữ/publish có lý do. | M12: US-AGENT-01 feedback; AN-AC-06; US-STEWARD-01 governed learning; US-PM-01 effectiveness | N12: 4 core + 1 reserve | O12: G7
A13: M8 | B13: Tích hợp, vận hành và bàn giao | C13: W13–W14 | D13: 46405 | E13: 46416 | F13: Chứng minh phạm vi demo 5 user stories; chuẩn bị release tái lập và ghi trung thực khoảng cách production. | G13: G7 PASS; live cloud cần account/budget/approval và reviewer; thiếu thì cloud gate BLOCKED, local demo vẫn báo riêng. | H13: G0–G7 evidence; candidate app/model/index/graph/policy; frozen eval; resource access. | I13: Release bundle, 5 UAT demos, eval suite, deploy/IaC package, runbooks, rollback evidence và coverage ledger. | J13: MOD-01..MOD-12 | K13: Docker; GitHub Actions; Helm/Terraform/EKS target; OTel/Prometheus; pytest; load harness | L13: Tái dựng từ manifest; chạy 5 persona; ngắt dependency; rollback app/model/knowledge; xem báo cáo thật. | M13: Tất cả stories ở phạm vi demo; production/business KPI là gate riêng không tự nhận đã đạt | N13: 8 core + 2 reserve | O13: G8

Sheet WBS
A1: WORK BREAKDOWN STRUCTURE | lịch từng công việc
A2: 1 người • 26/10/2026–31/01/2027 • 14 tuần • ngày T2–T6; 01/01 dành cho nghỉ dự kiến • màu biểu thị trạng thái kế hoạch
A3: ← Cover Page
B4: Người thực hiện: Trần Đình Khương | mọi vai trò kỹ thuật đều do cùng một người đảm nhiệm.
B5: Not Started / In Progress / Done / Blocked / Deferred / Contingency
B6: Lịch và effort tính theo 0,5 ngày; xem Task Details để biết buổi bắt đầu và dependency.
B8: Task | F8: Start date | G8: End date | H8: Responsibility | I8: Deliverable | J8: Task Status | K8: W1 | R8: W2 | Y8: W3 | AF8: W4 | AM8: W5 | AT8: W6 | BA8: W7 | BH8: W8 | BO8: W9 | BV8: W10 | CC8: W11 | CJ8: W12 | CQ8: W13 | CX8: W14
K9: T2 | L9: T3 | M9: T4 | N9: T5 | O9: T6 | P9: T7 | Q9: CN | R9: T2 | S9: T3 | T9: T4 | U9: T5 | V9: T6 | W9: T7 | X9: CN | Y9: T2 | Z9: T3 | AA9: T4 | AB9: T5 | AC9: T6 | AD9: T7 | AE9: CN | AF9: T2 | AG9: T3 | AH9: T4 | AI9: T5 | AJ9: T6 | AK9: T7 | AL9: CN | AM9: T2 | AN9: T3 | AO9: T4 | AP9: T5 | AQ9: T6 | AR9: T7 | AS9: CN | AT9: T2 | AU9: T3 | AV9: T4 | AW9: T5 | AX9: T6 | AY9: T7 | AZ9: CN | BA9: T2 | BB9: T3 | BC9: T4 | BD9: T5 | BE9: T6 | BF9: T7 | BG9: CN | BH9: T2 | BI9: T3 | BJ9: T4 | BK9: T5 | BL9: T6 | BM9: T7 | BN9: CN | BO9: T2 | BP9: T3 | BQ9: T4 | BR9: T5 | BS9: T6 | BT9: T7 | BU9: CN | BV9: T2 | BW9: T3 | BX9: T4 | BY9: T5 | BZ9: T6 | CA9: T7 | CB9: CN | CC9: T2 | CD9: T3 | CE9: T4 | CF9: T5 | CG9: T6 | CH9: T7 | CI9: CN | CJ9: T2 | CK9: T3 | CL9: T4 | CM9: T5 | CN9: T6 | CO9: T7 | CP9: CN | CQ9: T2 | CR9: T3 | CS9: T4 | CT9: T5 | CU9: T6 | CV9: T7 | CW9: CN | CX9: T2 | CY9: T3 | CZ9: T4 | DA9: T5 | DB9: T6 | DC9: T7 | DD9: CN
K10: 46321 | L10: 46322 | M10: 46323 | N10: 46324 | O10: 46325 | P10: 46326 | Q10: 46327 | R10: 46328 | S10: 46329 | T10: 46330 | U10: 46331 | V10: 46332 | W10: 46333 | X10: 46334 | Y10: 46335 | Z10: 46336 | AA10: 46337 | AB10: 46338 | AC10: 46339 | AD10: 46340 | AE10: 46341 | AF10: 46342 | AG10: 46343 | AH10: 46344 | AI10: 46345 | AJ10: 46346 | AK10: 46347 | AL10: 46348 | AM10: 46349 | AN10: 46350 | AO10: 46351 | AP10: 46352 | AQ10: 46353 | AR10: 46354 | AS10: 46355 | AT10: 46356 | AU10: 46357 | AV10: 46358 | AW10: 46359 | AX10: 46360 | AY10: 46361 | AZ10: 46362 | BA10: 46363 | BB10: 46364 | BC10: 46365 | BD10: 46366 | BE10: 46367 | BF10: 46368 | BG10: 46369 | BH10: 46370 | BI10: 46371 | BJ10: 46372 | BK10: 46373 | BL10: 46374 | BM10: 46375 | BN10: 46376 | BO10: 46377 | BP10: 46378 | BQ10: 46379 | BR10: 46380 | BS10: 46381 | BT10: 46382 | BU10: 46383 | BV10: 46384 | BW10: 46385 | BX10: 46386 | BY10: 46387 | BZ10: 46388 | CA10: 46389 | CB10: 46390 | CC10: 46391 | CD10: 46392 | CE10: 46393 | CF10: 46394 | CG10: 46395 | CH10: 46396 | CI10: 46397 | CJ10: 46398 | CK10: 46399 | CL10: 46400 | CM10: 46401 | CN10: 46402 | CO10: 46403 | CP10: 46404 | CQ10: 46405 | CR10: 46406 | CS10: 46407 | CT10: 46408 | CU10: 46409 | CV10: 46410 | CW10: 46411 | CX10: 46412 | CY10: 46413 | CZ10: 46414 | DA10: 46415 | DB10: 46416 | DC10: 46417 | DD10: 46418
B11: M0 | E11: Thiết kế chatbot và khóa phạm vi | F11: 46321 | G11: 46325 | H11: Trần Đình Khương | I11: Thiết kế chatbot, contract v1, wireframe, backlog, quyết định kỹ thuật và bộ kịch bản nghiệm thu. | J11: =IF(COUNTIF(J12:J16,"Done")=5,"Done",IF(COUNTIF(J12:J16,"Blocked")>0,"Blocked",IF(COUNTIF(J12:J16,"Done")+COUNTIF(J12:J16,"In Progress")>0,"In Progress","Not Started"))) | K11: • | L11: • | M11: • | N11: • | O11: •
D12: M0.1 | E12: Audit repo và lập danh mục yêu cầu | F12: 46321 | G12: 46321 | H12: Trần Đình Khương | I12: Baseline inventory; Source Register; traceability IDs; danh sách mâu thuẫn 0.5 ngày • AM • sau START | J12: Not Started | K12: •
D13: M0.2 | E13: Thiết kế UX chatbot, phạm vi và luồng hội thoại | F13: 46321 | G13: 46322 | H13: Trần Đình Khương | I13: Wireframe + conversation flow + scope MVP chatbot tuần 4 1 ngày • PM • sau M0.1 | J13: Not Started | K13: • | L13: •
D14: M0.3 | E14: Khóa contract, dữ liệu, công nghệ và API | F14: 46322 | G14: 46323 | H14: Trần Đình Khương | I14: ADR + schema/chat examples; OpenAPI dự kiến; bảng module; capability/provider matrix 1 ngày • PM • sau M0.2 | J14: Not Started | L14: • | M14: •
D15: M0.4 | E15: Thiết lập nền phát triển và thiết kế nghiệm thu | F15: 46323 | G15: 46324 | H15: Trần Đình Khương | I15: Khung ứng dụng có smoke; test plan và rubric; baseline measurement protocol 1 ngày • PM • sau M0.3 | J15: Not Started | M15: • | N15: •
D16: M0.G | E16: G0 — Review, nghiệm thu và báo cáo giai đoạn | F16: 46324 | G16: 46324 | H16: Trần Đình Khương | I16: docs/reports/milestones/m0-review.md; checklist; demo; manifest phiên bản 0.5 ngày • PM • sau M0.4 | J16: Not Started | N16: ◆
D17: M0.B | E17: Dự phòng sửa lỗi, tích hợp hoặc nghỉ theo lịch thực tế | F17: 46325 | G17: 46325 | H17: Trần Đình Khương | I17: Gate được kiểm tra lại; nhật ký sử dụng dự phòng và lịch cập nhật Reserve | J17: Contingency | O17: •
B18: M1 | E18: Chuẩn hóa dữ liệu chính sách cho chatbot | F18: 46328 | G18: 46332 | H18: Trần Đình Khương | I18: PolicyDocument/PolicyChunk đã duyệt; catalog nguồn; ingest report; policy-QA và privacy fixtures. | J18: =IF(COUNTIF(J19:J23,"Done")=5,"Done",IF(COUNTIF(J19:J23,"Blocked")>0,"Blocked",IF(COUNTIF(J19:J23,"Done")+COUNTIF(J19:J23,"In Progress")>0,"In Progress","Not Started"))) | R18: • | S18: • | T18: • | U18: • | V18: •
D19: M1.1 | E19: Kiểm kê và tiếp nhận snapshot crawler | F19: 46328 | G19: 46328 | H19: Trần Đình Khương | I19: source_inventory.csv; raw manifest có URL, hash, crawl time, status 0.5 ngày • AM • sau M0.G | J19: Not Started | R19: •
D20: M1.2 | E20: Làm sạch, chia đoạn và gắn provenance | F20: 46328 | G20: 46329 | H20: Trần Đình Khương | I20: policies_clean.jsonl; policy_chunks.jsonl; cleaning QA report 1 ngày • PM • sau M1.1 | J20: Not Started | R20: • | S20: •
D21: M1.3 | E21: Policy catalog, trạng thái duyệt và PII boundary | F21: 46329 | G21: 46330 | H21: Trần Đình Khương | I21: Registry migrations; policy versions; masking service; fixture assertions 1 ngày • PM • sau M1.2 | J21: Not Started | S21: • | T21: •
D22: M1.4 | E22: Tạo bộ đánh giá chatbot và privacy ban đầu | F22: 46330 | G22: 46331 | H22: Trần Đình Khương | I22: golden_policy_queries.jsonl; chat_eval.jsonl; pii_eval.jsonl + manifests 1 ngày • PM • sau M1.3 | J22: Not Started | T22: • | U22: •
D23: M1.G | E23: G1 — Review, nghiệm thu và báo cáo giai đoạn | F23: 46331 | G23: 46331 | H23: Trần Đình Khương | I23: docs/reports/milestones/m1-review.md; checklist; demo; manifest phiên bản 0.5 ngày • PM • sau M1.4 | J23: Not Started | U23: ◆
D24: M1.B | E24: Dự phòng sửa lỗi, tích hợp hoặc nghỉ theo lịch thực tế | F24: 46332 | G24: 46332 | H24: Trần Đình Khương | I24: Gate được kiểm tra lại; nhật ký sử dụng dự phòng và lịch cập nhật Reserve | J24: Contingency | V24: •
B25: M2 | E25: Chatbot RAG đầu tiên chạy xuyên suốt | F25: 46335 | G25: 46346 | H25: Trần Đình Khương | I25: Chat UI + API + history + retrieval + grounded generation; Docker demo; báo cáo benchmark ban đầu. | J25: =IF(COUNTIF(J26:J34,"Done")=9,"Done",IF(COUNTIF(J26:J34,"Blocked")>0,"Blocked",IF(COUNTIF(J26:J34,"Done")+COUNTIF(J26:J34,"In Progress")>0,"In Progress","Not Started"))) | Y25: • | Z25: • | AA25: • | AB25: • | AC25: • | AF25: • | AG25: • | AH25: • | AI25: • | AJ25: •
D26: M2.1 | E26: Lập chỉ mục và retrieval có bộ lọc | F26: 46335 | G26: 46336 | H26: Trần Đình Khương | I26: Index build pipeline; retrieval service; source resolver; index manifest 1.5 ngày • AM • sau M1.G | J26: Not Started | Y26: • | Z26: •
D27: M2.2 | E27: Benchmark BM25, dense và hybrid RRF | F27: 46336 | G27: 46337 | H27: Trần Đình Khương | I27: retrieval_policy_baseline.json + report + selected config 1 ngày • PM • sau M2.1 | J27: Not Started | Z27: • | AA27: •
D28: M2.3 | E28: Đánh giá reranker trên tập nhỏ | F28: 46337 | G28: 46337 | H28: Trần Đình Khương | I28: Reranker adapter; enable/disable ADR và giới hạn tài nguyên 0.5 ngày • PM • sau M2.2 | J28: Not Started | AA28: •
D29: M2.4 | E29: Sinh câu trả lời có nguồn và kiểm soát đầu ra | F29: 46338 | G29: 46338 | H29: Trần Đình Khương | I29: LLM service + guardrails + Answer contract 1 ngày • AM • sau M2.3 | J29: Not Started | AB29: •
D30: M2.5 | E30: API chat, phiên và bộ nhớ nhiều lượt | F30: 46339 | G30: 46342 | H30: Trần Đình Khương | I30: Conversation service; migrations; session/history endpoints; auth integration 1.5 ngày • AM • sau M2.4 | J30: Not Started | AC30: • | AF30: •
D31: M2.6 | E31: Giao diện chatbot và nguồn tham khảo | F31: 46342 | G31: 46343 | H31: Trần Đình Khương | I31: Buyer Chat trong apps/web chạy với backend thật; UI smoke scripts 1.5 ngày • PM • sau M2.5 | J31: Not Started | AF31: • | AG31: •
D32: M2.7 | E32: Telemetry, đóng gói demo và xử lý dependency fail | F32: 46344 | G32: 46344 | H32: Trần Đình Khương | I32: Compose demo; logs/traces; run instructions 0.5 ngày • AM • sau M2.6 | J32: Not Started | AH32: •
D33: M2.8 | E33: Đánh giá chatbot end-to-end và sửa lỗi | F33: 46344 | G33: 46345 | H33: Trần Đình Khương | I33: chatbot_mvp_eval report; demo recording; regression suite 1 ngày • PM • sau M2.7 | J33: Not Started | AH33: • | AI33: •
D34: M2.G | E34: G2 — Review, nghiệm thu và báo cáo giai đoạn | F34: 46345 | G34: 46345 | H34: Trần Đình Khương | I34: docs/reports/milestones/m2-review.md; checklist; demo; manifest phiên bản 0.5 ngày • PM • sau M2.8 | J34: Not Started | AI34: ◆
D35: M2.B | E35: Dự phòng sửa lỗi, tích hợp hoặc nghỉ theo lịch thực tế | F35: 46346 | G35: 46346 | H35: Trần Đình Khương | I35: Gate được kiểm tra lại; nhật ký sử dụng dự phòng và lịch cập nhật Reserve | J35: Contingency | AJ35: •
B36: M3 | E36: Chatbot theo đơn hàng và Copilot CSKH | F36: 46349 | G36: 46360 | H36: Trần Đình Khương | I36: Policy engine + customer tools + FSM + Agent Workspace; ticket/action/outcome và phản hồi được lưu. | J36: =IF(COUNTIF(J37:J45,"Done")=9,"Done",IF(COUNTIF(J37:J45,"Blocked")>0,"Blocked",IF(COUNTIF(J37:J45,"Done")+COUNTIF(J37:J45,"In Progress")>0,"In Progress","Not Started"))) | AM36: • | AN36: • | AO36: • | AP36: • | AQ36: • | AT36: • | AU36: • | AV36: • | AW36: • | AX36: •
D37: M3.1 | E37: Mô hình đơn hàng, ticket, action và outcome | F37: 46349 | G37: 46349 | H37: Trần Đình Khương | I37: Relational seed + schema + ticket lifecycle endpoints 1 ngày • AM • sau M2.G | J37: Not Started | AM37: •
D38: M3.2 | E38: Tra cứu đơn hàng có xác thực và kiểm soát truy cập | F38: 46350 | G38: 46350 | H38: Trần Đình Khương | I38: Customer context service + tool schemas + seed CRM adapter 1 ngày • AM • sau M3.1 | J38: Not Started | AN38: •
D39: M3.3 | E39: Policy engine xác định quyền lợi bằng rule | F39: 46351 | G39: 46351 | H39: Trần Đình Khương | I39: PolicyDecision service; rule tests; evidence-linked decision log 1 ngày • AM • sau M3.2 | J39: Not Started | AO39: •
D40: M3.4 | E40: FSM resolution, MCP tools và reflection hữu hạn | F40: 46352 | G40: 46353 | H40: Trần Đình Khương | I40: Resolution orchestrator; /api/v1/resolution/draft nối thật; tool integration tests 1.5 ngày • AM • sau M3.3 | J40: Not Started | AP40: • | AQ40: •
D41: M3.5 | E41: Agent Workspace: context, evidence và review | F41: 46353 | G41: 46356 | H41: Trần Đình Khương | I41: Agent Copilot trong apps/web + review endpoints; browser flows 1.5 ngày • PM • sau M3.4 | J41: Not Started | AQ41: • | AT41: •
...

Sheet Task Details
A1: TASK DETAILS | kế hoạch thực hiện và tiêu chí hoàn thành
A2: Input/Output là contract/deliverable dự kiến. Evidence hiện chưa có; chỉ cập nhật Done khi đạt gate và lưu bằng chứng. Effort 0,5 ngày = 4 giờ theo giả định.
A3: ← Cover Page
A4: Task ID | B4: Milestone | C4: Công việc | D4: Bắt đầu | E4: Kết thúc | F4: Buổi đầu | G4: Ngày công | H4: Người thực hiện | I4: Vai trò đang đảm nhiệm | J4: Input | K4: Các bước thực hiện | L4: Output / artifact | M4: Modules | N4: Công nghệ | O4: Dependency | P4: I/O contract | Q4: Definition of Done | R4: Nguồn yêu cầu | S4: Scope/type | T4: Task Status (từ WBS) | U4: Evidence thực tế
A5: M0.1 | B5: M0 | C5: Audit repo và lập danh mục yêu cầu | D5: 46321 | E5: 46321 | F5: AM | G5: 0.5 | H5: Trần Đình Khương | I5: BA / kiến trúc | J5: Toàn bộ tài liệu hiện hữu và commit 9083135 | K5: Phân biệt mock với chức năng thật; kiểm kê crawler, schemas, CI, API; lập ma trận yêu cầu và ghi các doc tham chiếu bị thiếu. | L5: Baseline inventory; Source Register; traceability IDs; danh sách mâu thuẫn | M5: MOD-12 | N5: Git; Markdown; Python | O5: START | Q5: Không dùng số trả cứng trong API làm baseline; mỗi yêu cầu có nguồn và giai đoạn. | R5: SRC-01..SRC-10; SRC-16 | S5: Core | T5: ='WBS'!J12 | U5: Chưa có — điền đường dẫn báo cáo/commit/demo sau khi thực hiện
A6: M0.2 | B6: M0 | C6: Thiết kế UX chatbot, phạm vi và luồng hội thoại | D6: 46321 | E6: 46322 | F6: PM | G6: 1 | H6: Trần Đình Khương | I6: Product / UX | J6: US-BUY-01, US-AGENT-01, chính sách mẫu | K6: Thiết kế một apps/web với bốn khu vực Buyer Chat, Agent Copilot, Analyst BI & GraphRAG, Steward Queue cho năm personas; dùng chung layout, session, API client và citation viewer. Vẽ chat, history, lỗi, chuyển CSKH và thông tin thiếu; tách policy Q&A khỏi quyết định theo đơn hàng; route ẩn không thay kiểm quyền API. | L6: Wireframe + conversation flow + scope MVP chatbot tuần 4 | M6: MOD-01, MOD-03 | N6: React/TypeScript; design document | O6: M0.1 | P6: IO-01, IO-02 | Q6: MVP trả lời có nguồn và nhớ ngữ cảnh; eligibility cá nhân thuộc M3, root cause xác nhận thuộc M6. | R6: SRC-02 §3,5,7.9; SRC-03; SRC-04 | S6: Core | T6: ='WBS'!J13 | U6: Chưa có — điền đường dẫn báo cáo/commit/demo sau khi thực hiện
A7: M0.3 | B7: M0 | C7: Khóa contract, dữ liệu, công nghệ và API | D7: 46322 | E7: 46323 | F7: PM | G7: 1 | H7: Trần Đình Khương | I7: Backend / kiến trúc | J7: M0.1–M0.2; schemas hiện tại; Decisions | K7: Chọn LLM/embedding qua smoke tiếng Việt, ngân sách và khả năng truy cập; giữ API /api/v1; khóa ChatMessageRequest/Response (product_ref/order_ref optional), Citation phân loại nguồn và ABSA prediction có version ở cấp kết quả; chốt namespace, ID, policy version, memory, timeout. Ghi ADR DEC-15/16/17 cho PostgreSQL stack, apps/web và lựa chọn FSM/LangGraph; không làm hai orchestrator. Ghi source-of-truth theo SRC-02 §8.2: CRM/live orders, approved Policy Registry, versioned graph và prediction tables; Redis/Qdrant là cache/index. Khóa profile demo và architecture-target riêng (DEC-18), thời điểm đo latency và effort còn thiếu tại G0. | L7: ADR + schema/chat examples; OpenAPI dự kiến; bảng module; capability/provider matrix | M7: MOD-01, MOD-02, MOD-03, MOD-04, MOD-12 | N7: Python 3.11/3.12; Poetry lock; FastAPI; Pydantic; PostgreSQL; Redis; Qdrant | O7: M0.2 | P7: IO-01..IO-05; IO-08; IO-10 | Q7: Có chính sách session ownership, context limit, không đưa raw PII ra LLM; cloud/GPU thiếu phải ghi tác động. | R7: SRC-02 §5,8,9; SRC-06; SRC-07; SRC-16 | S7: Core | T7: ='WBS'!J14 | U7: Chưa có — điền đường dẫn báo cáo/commit/demo sau khi thực hiện
A8: M0.4 | B8: M0 | C8: Thiết lập nền phát triển và thiết kế nghiệm thu | D8: 46323 | E8: 46324 | F8: PM | G8: 1 | H8: Trần Đình Khương | I8: Full-stack / QA | J8: ADR, wireframe, 5 stories và fixture nhỏ | K8: Tạo shell apps/web dùng chung và conversation API; khai báo/lock SQLAlchemy 2.x, psycopg[binary] 3.x, Alembic cho Python 3.11/3.12; tạo migration/schema ban đầu và transaction boundary; cấu hình môi trường, test scaffold, rubric eval, business baseline; chuẩn bị login/session boundary. | L8: Khung ứng dụng có smoke; test plan và rubric; baseline measurement protocol | M8: MOD-01, MOD-03, MOD-12 | N8: FastAPI; PostgreSQL migrations; React/TypeScript; pytest; Docker Compose; GitHub Actions | O8: M0.3 | P8: IO-01, IO-15 | Q8: Health thật phản ánh dependency; cấu hình không chứa secret; cài từ lockfile và kết nối PostgreSQL thật; migration từ DB rỗng và upgrade từ revision trước pass trên DB thử nghiệm, rollback/restore được mô tả; có kế hoạch 5 kịch bản E2E và negative paths; contract test cho policy Q&A không có product và citation sai nguồn/version. | R8: SRC-02 §15–17,21; SRC-04; SRC-16 | S8: Core | T8: ='WBS'!J15 | U8: Chưa có — điền đường dẫn báo cáo/commit/demo sau khi thực hiện
A9: M0.G | B9: M0 | C9: G0 — Review, nghiệm thu và báo cáo giai đoạn | D9: 46324 | E9: 46324 | F9: PM | G9: 0.5 | H9: Trần Đình Khương | I9: QA / quản lý dự án | J9: Các đầu ra và test/eval của M0 | K9: Chạy lại kịch bản nghiệm thu; đối chiếu yêu cầu; ghi PASS/FAIL/BLOCKED, số đo thực và kế hoạch sửa. Tự kiểm tra theo checklist; stakeholder xác nhận nếu có. | L9: docs/reports/milestones/m0-review.md; checklist; demo; manifest phiên bản | M9: MOD-12 | N9: pytest; eval reports; Git | O9: M0.4 | Q9: G0: khóa I/O, ADR, profile demo/architecture-target và ngưỡng eval; rà lại effort M0.4/M3.4/M4.5/M6.7/M8.2 theo smoke thực. Lịch 14 tuần là baseline, chưa chứng minh feasibility; thiếu resource/effort phải ghi blocker hoặc rebaseline. | R9: SRC-02 §21; SRC-03; SRC-04 | S9: Gate | T9: ='WBS'!J16 | U9: Chưa có — điền đường dẫn báo cáo/commit/demo sau khi thực hiện
A10: M0.B | B10: M0 | C10: Dự phòng sửa lỗi, tích hợp hoặc nghỉ theo lịch thực tế | D10: 46325 | E10: 46325 | F10: AM | G10: 1 | H10: Trần Đình Khương | I10: Dự phòng | J10: Blocker/failed gate hoặc ngày nghỉ đã xác nhận | K10: Ưu tiên sửa gate của giai đoạn; nếu chưa dùng thì giữ quỹ dự phòng. Không tự bổ sung tính năng. | L10: Gate được kiểm tra lại; nhật ký sử dụng dự phòng và lịch cập nhật | M10: MOD-12 | N10: Issue log; regression tests | O10: RESERVE — không phải quan hệ finish-to-start | Q10: Không vượt ngày kết thúc giai đoạn; nếu vượt phải rebaseline, không đánh dấu Done khi gate fail. | R10: DEC-01; DEC-02 | S10: Buffer | T10: ='WBS'!J17 | U10: Chưa có — điền đường dẫn báo cáo/commit/demo sau khi thực hiện
A11: M1.1 | B11: M1 | C11: Kiểm kê và tiếp nhận snapshot crawler | D11: 46328 | E11: 46328 | F11: AM | G11: 0.5 | H11: Trần Đình Khương | I11: Data engineering | J11: Các snapshot và báo cáo crawl đã có | K11: Đọc export qua adapter/file manifest; xác minh 52/56 là số ghi nhận lịch sử; chọn subset policy; kiểm tra lỗi/redirect/quyền sử dụng; giữ crawler độc lập. | L11: source_inventory.csv; raw manifest có URL, hash, crawl time, status | M11: MOD-02 | N11: Python; JSON; SHA-256 | O11: M0.G | P11: IO-03 | Q11: Không coi crawl thành công là đủ nội dung; không crawl lại toàn bộ nếu snapshot dùng được. | R11: SRC-10; SRC-11; SRC-12; SRC-13 | S11: Core | T11: ='WBS'!J19 | U11: Chưa có — điền đường dẫn báo cáo/commit/demo sau khi thực hiện
A12: M1.2 | B12: M1 | C12: Làm sạch, chia đoạn và gắn provenance | D12: 46328 | E12: 46329 | F12: PM | G12: 1 | H12: Trần Đình Khương | I12: Data engineering | J12: Raw HTML/text + inventory | K12: Bỏ navigation/footer; giữ heading, bảng, điều kiện/ngoại lệ; dedup; chunk theo điều khoản; xử lý missing/empty; lưu raw offset và hash ổn định. | L12: policies_clean.jsonl; policy_chunks.jsonl; cleaning QA report | M12: MOD-02 | N12: Python HTML parser; Pydantic; JSONL | O12: M1.1 | P12: IO-03, IO-04 | Q12: Mỗi đoạn resolve được nguồn; kiểm tra thủ công toàn bộ ~30 điều khoản demo; chạy lại không nhân đôi. | R12: SRC-06 §4–5,8; SRC-10 | S12: Core | T12: ='WBS'!J20 | U12: Chưa có — điền đường dẫn báo cáo/commit/demo sau khi thực hiện
A13: M1.3 | B13: M1 | C13: Policy catalog, trạng thái duyệt và PII boundary | D13: 46329 | E13: 46330 | F13: PM | G13: 1 | H13: Trần Đình Khương | I13: Backend / Data | J13: Policy chunks; draft registry; synthetic PII | K13: Lưu version/effective dates/scope/status; ngày không biết giữ unknown để duyệt; che PII text/logs; chỉ đưa policy approved vào index; tách dữ liệu đơn hàng. | L13: Registry migrations; policy versions; masking service; fixture assertions | M13: MOD-02, MOD-06, MOD-12 | N13: PostgreSQL; Pydantic; regex + NER; pytest | O13: M1.2 | P13: IO-04, IO-07 | Q13: Draft/expired/unknown-effectivity không dùng để kết luận quyền lợi; không raw PII trong index/prompt/log fixtures. | R13: SRC-02 §7.2,7.8,14; SRC-06 §2,5 | S13: Core | T13: ='WBS'!J21 | U13: Chưa có — điền đường dẫn báo cáo/commit/demo sau khi thực hiện
A14: M1.4 | B14: M1 | C14: Tạo bộ đánh giá chatbot và privacy ban đầu | D14: 46330 | E14: 46331 | F14: PM | G14: 1 | H14: Trần Đình Khương | I14: QA / Data | J14: ~30 clauses đã duyệt; rubric M0.4 | K14: Soạn 40 policy questions có relevance labels và expected sources; tách tuning/held-out theo intent/document; 20 hội thoại nhiều lượt; sinh 500 PII fixtures rồi kiểm mẫu thủ công; thêm expired/conflict/no-evidence/injection. | L14: golden_policy_queries.jsonl; chat_eval.jsonl; pii_eval.jsonl + manifests | M14: MOD-02, MOD-12 | N14: JSONL; Python; pytest; annotation rubric | O14: M1.3 | P14: IO-14 | Q14: Có no-answer và follow-up; test set không dùng tune prompt; synthetic PII được ghi đúng nguồn và giới hạn. | R14: SRC-06 §2,4,6; SRC-07 §ABSA/Retrieval eval | S14: Core | T14: ='WBS'!J22 | U14: Chưa có — điền đường dẫn báo cáo/commit/demo sau khi thực hiện
A15: M1.G | B15: M1 | C15: G1 — Review, nghiệm thu và báo cáo giai đoạn | D15: 46331 | E15: 46331 | F15: PM | G15: 0.5 | H15: Trần Đình Khương | I15: QA / quản lý dự án | J15: Các đầu ra và test/eval của M1 | K15: Chạy lại kịch bản nghiệm thu; đối chiếu yêu cầu; ghi PASS/FAIL/BLOCKED, số đo thực và kế hoạch sửa. Tự kiểm tra theo checklist; stakeholder xác nhận nếu có. | L15: docs/reports/milestones/m1-review.md; checklist; demo; manifest phiên bản | M15: MOD-12 | N15: pytest; eval reports; Git | O15: M1.4 | Q15: G1: 5–10 policies/~30 clauses đã duyệt, truy nguồn đầy đủ; 40 queries + 20 hội thoại; privacy fixtures; ingestion idempotent. | R15: SRC-06; SRC-10; SRC-04 | S15: Gate | T15: ='WBS'!J23 | U15: Chưa có — điền đường dẫn báo cáo/commit/demo sau khi thực hiện
A16: M1.B | B16: M1 | C16: Dự phòng sửa lỗi, tích hợp hoặc nghỉ theo lịch thực tế | D16: 46332 | E16: 46332 | F16: AM | G16: 1 | H16: Trần Đình Khương | I16: Dự phòng | J16: Blocker/failed gate hoặc ngày nghỉ đã xác nhận | K16: Ưu tiên sửa gate của giai đoạn; nếu chưa dùng thì giữ quỹ dự phòng. Không tự bổ sung tính năng. | L16: Gate được kiểm tra lại; nhật ký sử dụng dự phòng và lịch cập nhật | M16: MOD-12 | N16: Issue log; regression tests | O16: RESERVE — không phải quan hệ finish-to-start | Q16: Không vượt ngày kết thúc giai đoạn; nếu vượt phải rebaseline, không đánh dấu Done khi gate fail. | R16: DEC-01; DEC-02 | S16: Buffer | T16: ='WBS'!J24 | U16: Chưa có — điền đường dẫn báo cáo/commit/demo sau khi thực hiện
A17: M2.1 | B17: M2 | C17: Lập chỉ mục và retrieval có bộ lọc | D17: 46335 | E17: 46336 | F17: AM | G17: 1.5 | H17: Trần Đình Khương | I17: Backend / ML | J17: Policy chunks và index contract | K17: Tạo namespace policies, dense + BM25 baseline, metadata indexes; enforce approved/effective/tenant filters; build snapshot và readiness; citations trả clause ID + URL. | L17: Index build pipeline; retrieval service; source resolver; index manifest | M17: MOD-04 | N17: Qdrant; sentence-transformers; BM25; Python | O17: M1.G | P17: IO-04, IO-05 | Q17: Count/hash đối chiếu; empty/index unavailable có trạng thái rõ; nguồn thật, bộ lọc đúng trên fixtures. | R17: SRC-02 §7.5; SRC-06 §4; SRC-07 Retrieval | S17: Core | T17: ='WBS'!J26 | U17: Chưa có — điền đường dẫn báo cáo/commit/demo sau khi thực hiện
A18: M2.2 | B18: M2 | C18: Benchmark BM25, dense và hybrid RRF | D18: 46336 | E18: 46337 | F18: PM | G18: 1 | H18: Trần Đình Khương | I18: ML / QA | J18: Policy query tuning + held-out; index snapshots | K18: Đánh giá riêng ba mode cùng corpus/query; tune chỉ trên dev; đo Recall@5/@10, MRR, nDCG, p95, memory và cost; chốt mode theo kết quả. | L18: retrieval_policy_baseline.json + report + selected config | M18: MOD-04 | N18: rank-bm25; Qdrant; RRF; Python eval | O18: M2.1 | P18: IO-14 | Q18: Không mặc định hybrid thắng; giữ per-query outputs và manifest; số liệu chưa đạt phải ghi FAIL. | R18: SRC-02 §13.2; SRC-07 Retrieval; WEB-02 | S18: Core | T18: ='WBS'!J27 | U18: Chưa có — điền đường dẫn báo cáo/commit/demo sau khi thực hiện
A19: M2.3 | B19: M2 | C19: Đánh giá reranker trên tập nhỏ | D19: 46337 | E19: 46337 | F19: PM | G19: 0.5 | H19: Trần Đình Khương | I19: ML | J19: Candidates và benchmark M2.2 | K19: Thử BGE cross-encoder Top-50 → Top-5/10; so chất lượng/latency theo rubric đã khóa; giữ feature flag nếu chưa có gain. | L19: Reranker adapter; enable/disable ADR và giới hạn tài nguyên | M19: MOD-04 | N19: BGE cross-encoder candidate; sentence-transformers | O19: M2.2 | P19: IO-05 | Q19: Chỉ bật runtime nếu held-out gain và latency budget đạt; score không được gọi là xác suất đúng. | R19: SRC-02 §7.5; SRC-07 RET-AC-08 | S19: Core | T19: ='WBS'!J28 | U19: Chưa có — điền đường dẫn báo cáo/commit/demo sau khi thực hiện
A20: M2.4 | B20: M2 | C20: Sinh câu trả lời có nguồn và kiểm soát đầu ra | D20: 46338 | E20: 46338 | F20: AM | G20: 1 | H20: Trần Đình Khương | I20: Backend / LLM | J20: EvidencePack; model config; chat eval | K20: Viết client có timeout/retry hữu hạn; prompt tiếng Việt theo evidence; schema output; kiểm citation tồn tại/đúng clause và claims; abstain hoặc hỏi thêm; ghi prompt/model version. Tách claim verification, schema validation, policy compliance và output PII filter; kiểm đủ từng bước, không coi JSON hợp lệ là grounded. | L20: LLM service + guardrails + Answer contract | M20: MOD-03 | N20: LLM API cấu hình; HTTP client; Pydantic; pytest | O20: M2.3 | P20: IO-02, IO-05 | Q20: Không bịa policy/refund; không có nguồn thì không khẳng định; schema invalid không trả nội dung chưa kiểm. | R20: SRC-02 §7.9; SRC-04; SRC-06 §6 | S20: Core | T20: ='WBS'!J29 | U20: Chưa có — điền đường dẫn báo cáo/commit/demo sau khi thực hiện
A21: M2.5 | B21: M2 | C21: API chat, phiên và bộ nhớ nhiều lượt | D21: 46339 | E21: 46342 | F21: AM | G21: 1.5 | H21: Trần Đình Khương | I21: Backend | J21: ChatRequest/Response, generation service, PostgreSQL | K21: POST /api/v1/chat/messages; lưu message/request_id/idempotency; ownership; sliding context và summary; rewrite follow-up từ lịch sử; hủy/timeout; chỉ truy lịch sử được phép. Đặt Redis sliding-window rate limit trước gọi retrieval/LLM, quota token/request, input size và timeout; Redis unavailable trả lỗi có kiểm soát. M2 route bằng intent/rules policy_query/out_of_scope; classifier đầy đủ bổ sung ở M4. | L21: Conversation service; migrations; session/history endpoints; auth integration | M21: MOD-01 | N21: FastAPI; PostgreSQL; Redis cache; Pydantic | O21: M2.4 | P21: IO-01, IO-02 | Q21: Hai phiên không lẫn dữ liệu; retry không nhân đôi message; follow-up giữ policy context; không bắt nhập product cho câu hỏi chung. Test 429/Retry-After, quota và Redis failure trước gọi LLM; request bị từ chối không tiêu token. | R21: SRC-02 §5.4,7.9; SRC-16 | S21: Core | T21: ='WBS'!J30 | U21: Chưa có — điền đường dẫn báo cáo/commit/demo sau khi thực hiện
A22: M2.6 | B22: M2 | C22: Giao diện chatbot và nguồn tham khảo | D22: 46342 | E22: 46343 | F22: PM | G22: 1.5 | H22: Trần Đình Khương | I22: Frontend | J22: Wireframe; chat/history API | K22: Tạo màn chat, lịch sử, nguồn clickable, error/retry, loading, clarification và nút chuyển hỗ trợ; nối API thật; kiểm desktop/mobile và accessibility cơ bản. | L22: Buyer Chat trong apps/web chạy với backend thật; UI smoke scripts | M22: MOD-01 | N22: React; TypeScript; CSS; browser tests | O22: M2.5 | P22: IO-01, IO-02 | Q22: Cả happy path và thiếu bằng chứng hoạt động; trạng thái chờ không tạo nội dung giả; nguồn mở đúng clause/doc. | R22: SRC-03 US-BUY-01; SRC-02 §3.1; WEB-04 | S22: Core | T22: ='WBS'!J31 | U22: Chưa có — điền đường dẫn báo cáo/commit/demo sau khi thực hiện
A23: M2.7 | B23: M2 | C23: Telemetry, đóng gói demo và xử lý dependency fail | D23: 46344 | E23: 46344 | F23: AM | G23: 0.5 | H23: Trần Đình Khương | I23: Platform | J23: Chat app + retrieval + generation | K23: Trace request→retrieval→LLM; đếm token/cost/latency; log đã redacted; Compose startup và readiness thật; thử Qdrant/LLM timeout. | L23: Compose demo; logs/traces; run instructions | M23: MOD-12 | N23: Docker Compose; OpenTelemetry; structured logging | O23: M2.6 | P23: IO-15 | Q23: Có source/model/index/prompt version; không success giả khi dependency hỏng. | R23: SRC-02 §15–16; SRC-07 NFR | S23: Core | T23: ='WBS'!J32 | U23: Chưa có — điền đường dẫn báo cáo/commit/demo sau khi thực hiện
A24: M2.8 | B24: M2 | C24: Đánh giá chatbot end-to-end và sửa lỗi | D24: 46344 | E24: 46345 | F24: PM | G24: 1 | H24: Trần Đình Khương | I24: QA | J24: 40 policy queries; 20 dialogues; privacy/attack cases | K24: Chạy suite frozen; review answer/citation; kiểm response ownership, injection, expired policy, no-answer và request duplicate; ghi latency thực và hạn chế. | L24: chatbot_mvp_eval report; demo recording; regression suite | M24: MOD-01, MOD-03, MOD-04, MOD-12 | N24: pytest; browser tests; human rubric | O24: M2.7 | P24: IO-14 | Q24: MVP: ≥90% policy QA rubric pass (đề xuất); citation completeness ≥95%; 0 unsupported promises/PII leaks trên suite; full response <60s trên kịch bản chuẩn. | R24: SRC-04; SRC-02 §9,13; SRC-06 §6 | S24: Core | T24: ='WBS'!J33 | U24: Chưa có — điền đường dẫn báo cáo/commit/demo sau khi thực hiện
A25: M2.G | B25: M2 | C25: G2 — Review, nghiệm thu và báo cáo giai đoạn | D25: 46345 | E25: 46345 | F25: PM | G25: 0.5 | H25: Trần Đình Khương | I25: QA / quản lý dự án | J25: Các đầu ra và test/eval của M2 | K25: Chạy lại kịch bản nghiệm thu; đối chiếu yêu cầu; ghi PASS/FAIL/BLOCKED, số đo thực và kế hoạch sửa. Tự kiểm tra theo checklist; stakeholder xác nhận nếu có. | L25: docs/reports/milestones/m2-review.md; checklist; demo; manifest phiên bản | M25: MOD-12 | N25: pytest; eval reports; Git | O25: M2.8 | Q25: G2: chatbot UI→API→retrieval→LLM→citations chạy thật; multi-turn/fallback/privacy, claim/schema/policy/output filter và rate-limit/quota pass; benchmark retrieval/generation riêng. Chưa có ABSA/GraphRAG không được gọi hoàn thành full Buyer story. | R25: SRC-03 US-BUY-01; SRC-04; SRC-02 §21 | S25: Gate | T25: ='WBS'!J34 | U25: Chưa có — điền đường dẫn báo cáo/commit/demo sau khi thực hiện
A26: M2.B | B26: M2 | C26: Dự phòng sửa lỗi, tích hợp hoặc nghỉ theo lịch thực tế | D26: 46346 | E26: 46346 | F26: AM | G26: 1 | H26: Trần Đình Khương | I26: Dự phòng | J26: Blocker/failed gate hoặc ngày nghỉ đã xác nhận | K26: Ưu tiên sửa gate của giai đoạn; nếu chưa dùng thì giữ quỹ dự phòng. Không tự bổ sung tính năng. | L26: Gate được kiểm tra lại; nhật ký sử dụng dự phòng và lịch cập nhật | M26: MOD-12 | N26: Issue log; regression tests | O26: RESERVE — không phải quan hệ finish-to-start | Q26: Không vượt ngày kết thúc giai đoạn; nếu vượt phải rebaseline, không đánh dấu Done khi gate fail. | R26: DEC-01; DEC-02 | S26: Buffer | T26: ='WBS'!J35 | U26: Chưa có — điền đường dẫn báo cáo/commit/demo sau khi thực hiện
A27: M3.1 | B27: M3 | C27: Mô hình đơn hàng, ticket, action và outcome | D27: 46349 | E27: 46349 | F27: AM | G27: 1 | H27: Trần Đình Khương | I27: Backend / Data | J27: Seed specs + contracts M0 | K27: Migration customer/order/product/version/ticket/action/outcome; seed 5–10 sản phẩm, ~15 phiên bản, 200 orders; mọi dữ liệu demo có synthetic flag; thiết kế idempotency và timestamps. | L27: Relational seed + schema + ticket lifecycle endpoints | M27: MOD-05, MOD-06 | N27: PostgreSQL; Pydantic; migrations | O27: M2.G | P27: IO-06, IO-09 | Q27: Bridge keys nhất quán; FK hợp lệ; không giả lập 200 khách thật; lịch sử ticket không overwrite. | R27: SRC-02 §8; SRC-06 §5,8 | S27: Core | T27: ='WBS'!J37 | U27: Chưa có — điền đường dẫn báo cáo/commit/demo sau khi thực hiện
A28: M3.2 | B28: M3 | C28: Tra cứu đơn hàng có xác thực và kiểm soát truy cập | D28: 46350 | E28: 46350 | F28: AM | G28: 1 | H28: Trần Đình Khương | I28: Backend | J28: Orders + auth/session | K28: Implement query_customer_order và context adapter; kiểm order ownership trước đọc; chỉ expose trường cần; tìm region/service center; hỏi lại khi thiếu hoặc không khớp. Recall chỉ lấy ticket/order history được phép của đúng customer; working context/message buffer có giới hạn; playbook/rules có version là procedural memory, không coi lời hứa cũ trong ticket là policy hiện hành. | L28: Customer context service + tool schemas + seed CRM adapter | M28: MOD-05 | N28: FastAPI; PostgreSQL; typed tools; RBAC | O28: M3.1 | P28: IO-06 | Q28: Cross-customer access bị chặn; trạng thái unknown tách ineligible; raw PII không vào prompt/index/log. | R28: SRC-02 §3.1,7.2,14; SRC-06 §5 | S28: Core | T28: ='WBS'!J38 | U28: Chưa có — điền đường dẫn báo cáo/commit/demo sau khi thực hiện
A29: M3.3 | B29: M3 | C29: Policy engine xác định quyền lợi bằng rule | D29: 46351 | E29: 46351 | F29: AM | G29: 1 | H29: Trần Đình Khương | I29: Backend | J29: Approved policy rules; order context | K29: Match product/date/scope/version; evaluate eligibility; trả missing_fields, allowed/prohibited_actions; xử lý policy conflict/stale; trường hợp tiền/ngoại lệ cần người duyệt. | L29: PolicyDecision service; rule tests; evidence-linked decision log | M29: MOD-06 | N29: Python decision rules; PostgreSQL; Pydantic | O29: M3.2 | P29: IO-07 | Q29: Không dùng LLM quyết eligibility; ranh ngày mua/expiry đúng; policy ví dụ 365 ngày chỉ dùng synthetic fixture. | R29: SRC-02 §7.8; SRC-06 §5–6 | S29: Core | T29: ='WBS'!J39 | U29: Chưa có — điền đường dẫn báo cáo/commit/demo sau khi thực hiện
A30: M3.4 | B30: M3 | C30: FSM resolution, MCP tools và reflection hữu hạn | D30: 46352 | E30: 46353 | F30: AM | G30: 1.5 | H30: Trần Đình Khương | I30: Backend / orchestration | J30: Chat, policy decision, tools, ticket model | K30: Ingested→context→evidence→decision→draft→guarded→pending_review→approved/rejected/escalated; giới hạn 1 lượt bổ sung evidence và timeout; lưu state/version, review ID và audit trong PostgreSQL; approval/resume kiểm quyền, chống duyệt hai lần và stale draft; MCP adapter query order/check warranty/route ticket; Pydantic inputs và allowlist. Dùng một orchestrator theo DEC-17. Planning step tạo plan có kiểu: intent, nguồn evidence cần lấy, tool allowlist, missing fields và stop condition; sau M4 ánh xạ Triaged bằng ABSA thật. Chứng minh MCP bằng client/server local qua một transport được pin, tools/list và tools/call cho ba tool canonical; adapter gọi hàm Python riêng chưa đủ nghiệm thu MCP. | L30: Resolution orchestrator; /api/v1/resolution/draft nối thật; tool integration tests | M30: MOD-01, MOD-03, MOD-05, MOD-06 | N30: Python FSM; MCP SDK/adapter; FastAPI; Pydantic | O30: M3.3 | P30: IO-08 | Q30: Retry hoặc restart tại pending_review không mất draft và không lặp action; test approve/reject/resume, duplicate approval, stale draft, sai quyền và timeout; lỗi/thiếu evidence chuyển đúng hàng đợi; không tự xác nhận root cause; action cần approval không chạy trước duyệt. Checkpoint không thay action idempotency/transaction. Integration test MCP có input/output schema, denied tool, timeout và lỗi transport; lưu trace plan→tools→guardrails. Mapping trạng thái giữ tương ứng lifecycle SRC-05 §6.5. | R30: SRC-02 §7.9; SRC-05 L2,L5,L6 | S30: Core | T30: ='WBS'!J40 | U30: Chưa có — điền đường dẫn báo cáo/commit/demo sau khi thực hiện
A31: M3.5 | B31: M3 | C31: Agent Workspace: context, evidence và review | D31: 46353 | E31: 46356 | F31: PM | G31: 1.5 | H31: Trần Đình Khương | I31: Frontend | J31: Ticket/draft/citation APIs | K31: Ticket list/card: order, warranty, urgency, evidence/policy dates; approve/edit/reject với reason; specialist escalation; ABSA tạm hiển thị pending/manual; hypothesis label rõ. | L31: Agent Copilot trong apps/web + review endpoints; browser flows | M31: MOD-11 | N31: React; TypeScript; FastAPI; PostgreSQL | O31: M3.4 | P31: IO-08, IO-09, IO-13 | Q31: Agent đọc được bằng chứng trước duyệt; chỉnh sửa có tác giả/thời gian; không hiển thị hypothesis thành fact. | R31: SRC-02 §3.2; SRC-14 | S31: Core | T31: ='WBS'!J41 | U31: Chưa có — điền đường dẫn báo cáo/commit/demo sau khi thực hiện
A32: M3.6 | B32: M3 | C32: Lưu phản hồi cuối, outcome và business events | D32: 46357 | E32: 46357 | F32: AM | G32: 1 | H32: Trần Đình Khương | I32: Backend / Analytics | J32: Agent action + customer outcome | K32: Persist final response, sent/resolved/reopened/CSAT events và ticket owner; thu thập timestamps phục vụ FRT/AHT/MTTR/FCR; mapping complaint→ingest event cho ABSA về sau. | L32: Outcome API; audit events; metric dictionary và baseline captures | M32: MOD-06, MOD-09, MOD-11 | N32: PostgreSQL; Pydantic; event log | O32: M3.5 | P32: IO-09, IO-15 | Q32: Một action idempotent chỉ ghi một lần; outcome thiếu hiển thị unknown; log phiên bản policy/model/evidence/human reviewer. | R32: SRC-02 §3.1–3.4,8,13.5; SRC-04 | S32: Core | T32: ='WBS'!J42 | U32: Chưa có — điền đường dẫn báo cáo/commit/demo sau khi thực hiện
A33: M3.7 | B33: M3 | C33: Đánh giá resolution và luồng hỗ trợ | D33: 46358 | E33: 46358 | F33: AM | G33: 1 | H33: Trần Đình Khương | I33: QA | J33: 30 resolution cases giai đoạn đầu; order/privacy fixtures | K33: Test trong hạn/hết hạn/missing order/unconfirmed issue/prompt injection; approve/edit/reject/escalate; đo manual-vs-assisted cùng kịch bản; review chính sách và citation. | L33: Resolution eval v1; UAT agent/buyer; baseline report | M33: MOD-03, MOD-05, MOD-06, MOD-11 | N33: pytest; browser tests; JSONL rubric | O33: M3.6 | P33: IO-14 | Q33: 0 unsupported actions trên suite; 100% policy claim có clause/version; safety issue vào priority queue; chưa tuyên bố AHT giảm 40% từ dữ liệu demo. | R33: SRC-06 §6; SRC-02 BUY-AC/AG-AC; SRC-03 | S33: Core | T33: ='WBS'!J43 | U33: Chưa có — điền đường dẫn báo cáo/commit/demo sau khi thực hiện
A34: M3.8 | B34: M3 | C34: Cô lập công cụ và lỗi thực thi | D34: 46359 | E34: 46359 | F34: AM | G34: 0.5 | H34: Trần Đình Khương | I34: Platform / Security | J34: Tool adapters và action allowlist | K34: Thiết lập process/task timeout, restricted tool inputs, quyền tối thiểu; công cụ mô phỏng external action ghi rõ sandbox; đánh giá nhu cầu microVM như extension. | L34: Task isolation config; timeout/retry audit; microVM decision | M34: MOD-06, MOD-12 | N34: Process/task isolation; Docker; MCP adapter | O34: M3.7 | P34: IO-08 | Q34: Không thực thi shell tự do từ LLM; side effect có token/idempotency và approval; sandbox không bị trình bày như giao dịch thật. | R34: SRC-05 L5; SRC-02 §7.9 | S34: Core | T34: ='WBS'!J44 | U34: Chưa có — điền đường dẫn báo cáo/commit/demo sau khi thực hiện
A35: M3.G | B35: M3 | C35: G3 — Review, nghiệm thu và báo cáo giai đoạn | D35: 46359 | E35: 46359 | F35: PM | G35: 0.5 | H35: Trần Đình Khương | I35: QA / quản lý dự án | J35: Các đầu ra và test/eval của M3 | K35: Chạy lại kịch bản nghiệm thu; đối chiếu yêu cầu; ghi PASS/FAIL/BLOCKED, số đo thực và kế hoạch sửa. Tự kiểm tra theo checklist; stakeholder xác nhận nếu có. | L35: docs/reports/milestones/m3-review.md; checklist; demo; manifest phiên bản | M35: MOD-12 | N35: pytest; eval reports; Git | O35: M3.8 | Q35: G3: order ownership + deterministic policy + agent review/outcome pass; restart/resume/idempotency và ba MCP tools qua protocol có evidence; điều kiện thiếu được hỏi lại; có ticket tới specialist thật trong app. | R35: SRC-02 BUY-AC-02..05; AG-AC-01..05; SRC-04 | S35: Gate | T35: ='WBS'!J45 | U35: Chưa có — điền đường dẫn báo cáo/commit/demo sau khi thực hiện
A36: M3.B | B36: M3 | C36: Dự phòng sửa lỗi, tích hợp hoặc nghỉ theo lịch thực tế | D36: 46360 | E36: 46360 | F36: AM | G36: 1 | H36: Trần Đình Khương | I36: Dự phòng | J36: Blocker/failed gate hoặc ngày nghỉ đã xác nhận | K36: Ưu tiên sửa gate của giai đoạn; nếu chưa dùng thì giữ quỹ dự phòng. Không tự bổ sung tính năng. | L36: Gate được kiểm tra lại; nhật ký sử dụng dự phòng và lịch cập nhật | M36: MOD-12 | N36: Issue log; regression tests | O36: RESERVE — không phải quan hệ finish-to-start | Q36: Không vượt ngày kết thúc giai đoạn; nếu vượt phải rebaseline, không đánh dấu Done khi gate fail. | R36: DEC-01; DEC-02 | S36: Buffer | T36: ='WBS'!J46 | U36: Chưa có — điền đường dẫn báo cáo/commit/demo sau khi thực hiện
A37: M4.1 | B37: M4 | C37: Khóa taxonomy, splits và dataset provenance | D37: 46363 | E37: 46363 | F37: AM | G37: 1 | H37: Trần Đình Khương | I37: ML / Data | J37: UIT datasets + domain records + policy quyền dữ liệu | K37: Kiểm count/split chính thức thay vì áp tỷ lệ minh họa; map 10 aspects và nhóm macro; dedup leakage; giữ test locked; xác định labels span cho ATE; bổ sung delivery/service nếu thiếu. | L37: aspect_taxonomy_v1.yaml; train/dev/test parquet + data card/manifests | M37: MOD-07 | N37: Python; pandas; Parquet; schema validation | O37: M3.G | P37: IO-10, IO-14 | Q37: Không trộn test vào train; thiếu span labels không báo ATE đạt; vùng domain chưa đủ mẫu ghi hạn chế. | R37: SRC-06 §3; SRC-07 ABSA; SRC-02 §7.3 | S37: Core | T37: ='WBS'!J48 | U37: Chưa có — điền đường dẫn báo cáo/commit/demo sau khi thực hiện
